<?xml version="1.0" encoding="UTF-8"?>
<!--
            z    y
            ^   ^
            |  /
            | /
      _______________ > x
-->
<robot name="Cat">

  <link name="chassis">
    <collision>
      <origin rpy="0 0 0" xyz="0 0 0.005"/>
      <geometry>
        <box size="0.2 0.1 0.04"/>
      </geometry>
    </collision>
    <inertial>
      <mass value="0.4"/>
      <inertia ixx="0.0003866666666666668" ixy="0.0" ixz="0.0" iyy="0.001386666666666667" iyz="0.0" izz="0.001666666666666667"/>
    </inertial>
    <visual>
      <origin rpy="0 0 0" xyz="0 0 0.005"/>
      <geometry>
        <box size="0.2 0.1 0.04"/>
      </geometry>
      <material name="white">
        <color rgba="0.89 0.548 0.239 1"/>
      </material>
    </visual>
  </link>

  <link name="fl1_link">
    <collision>
      <origin rpy="0 0 0" xyz="-0.0 -0.005 0.01"/>
      <geometry>
        <box size="0.02 0.041 0.041"/>
      </geometry>
    </collision>
    <inertial>
      <mass value="0.07"/>
      <inertia ixx="1.961166666666667e-05" ixy="0.0" ixz="0.0" iyy="1.2139166666666669e-05" iyz="0.0" izz="1.2139166666666669e-05"/>
    </inertial>
    <visual>
      <origin rpy="0 0 0" xyz="-0.0 -0.005 0.01"/>
      <geometry>
        <box size="0.02 0.041 0.041"/>
      </geometry>
      <material name="white">
        <color rgba="0.0 0.56 0.854 1"/>
      </material>
    </visual>
  </link>
   
  <link name="fl2_link">
    <collision>
      <origin rpy="0 0 0" xyz="0 0 -0.03"/>
      <geometry>
        <box size="0.02 0.005 0.1"/>
      </geometry>
    </collision>
    <inertial>
      <mass value="0.07"/>
      <inertia ixx="5.847916666666669e-05" ixy="0.0" ixz="0.0" iyy="6.066666666666668e-05" iyz="0.0" izz="2.479166666666667e-06"/>
    </inertial>
    <visual>
      <origin rpy="0 0 0" xyz="0 0 -0.03"/>
      <geometry>
        <box size="0.02 0.005 0.1"/>
      </geometry>
      <material name="white">
        <color rgba="0.316 0.669 0.261 1"/>
      </material>
    </visual>
  </link>

  <link name="fl3_link">
    <collision>
      <origin rpy="0 0 0" xyz="0 0.0 -0.04"/>
      <geometry>
        <box size="0.01 0.005 0.09"/>
      </geometry>
    </collision>
    <inertial>
      <mass value="0.02"/>
      <inertia ixx="1.3541666666666666e-05" ixy="0.0" ixz="0.0" iyy="1.3666666666666664e-05" iyz="0.0" izz="2.0833333333333333e-07"/>
    </inertial>
    <visual>
      <origin rpy="0 0 0" xyz="0 0.0 -0.04"/>
      <geometry>
        <box size="0.01 0.005 0.09"/>
      </geometry>
      <material name="white">
        <color rgba="0.917 0.814 0.261 1"/>
      </material>
    </visual>
  </link>

  <link name="fl4_link">
    <collision>
      <origin rpy="0 0 0" xyz="0 0.0 0.01"/>
      <geometry>
        <sphere radius="0.01"/>
      </geometry>
    </collision>
    <inertial>
      <mass value="0.01"/>
      <inertia ixx="0.001" ixy="0.0" ixz="0.0" iyy="0.001" iyz="0.0" izz="0.001"/>
    </inertial>
    <contact>
        <friction_anchor/>
        <stiffness value="10000.0"/>
        <inertia_scaling value="0.1"/>
        <damping value="10.0"/>
        <lateral_friction value="1"/>
    </contact>
    <visual>
      <origin rpy="0 0 0" xyz="0 0.0 0.01"/>
      <geometry>
        <sphere radius="0.01"/>
      </geometry>
      <material name="white">
        <color rgba="1 1 1 1"/>
      </material>
    </visual>
  </link>

  <link name="fr1_link">
    <collision>
      <origin rpy="0 0 0" xyz="0.0 0.01 0.01"/>
      <geometry>
        <box size="0.02 0.041 0.041"/>
      </geometry>
    </collision>
    <inertial>
      <mass value="0.07"/>
      <inertia ixx="1.961166666666667e-05" ixy="0.0" ixz="0.0" iyy="1.2139166666666669e-05" iyz="0.0" izz="1.2139166666666669e-05"/>
    </inertial>
    <visual>
      <origin rpy="0 0 0" xyz="0.0 0.01 0.01"/>
      <geometry>
        <box size="0.02 0.041 0.041"/>
      </geometry>
      <material name="white">
        <color rgba="0.0 0.56 0.854 1"/>
      </material>
    </visual>
  </link>
   
  <link name="fr2_link">
    <collision>
      <origin rpy="0 0 0" xyz="0 0 -0.03"/>
      <geometry>
        <box size="0.02 0.005 0.1"/>
      </geometry>
    </collision>
    <inertial>
      <mass value="0.07"/>
      <inertia ixx="5.847916666666669e-05" ixy="0.0" ixz="0.0" iyy="6.066666666666668e-05" iyz="0.0" izz="2.479166666666667e-06"/>
    </inertial>
    <visual>
      <origin rpy="0 0 0" xyz="0 0 -0.03"/>
      <geometry>
        <box size="0.02 0.005 0.1"/>
      </geometry>
      <material name="white">
        <color rgba="0.316 0.669 0.261 1"/>
      </material>
    </visual>
  </link>

  <link name="fr3_link">
    <collision>
      <origin rpy="0 0 0" xyz="0 0.0 -0.04"/>
      <geometry>
        <box size="0.01 0.005 0.09"/>
      </geometry>
    </collision>
    <inertial>
      <mass value="0.05"/>
      <inertia ixx="3.3854166666666665e-05" ixy="0.0" ixz="0.0" iyy="3.416666666666666e-05" iyz="0.0" izz="5.208333333333334e-07"/>
    </inertial>
    <visual>
      <origin rpy="0 0 0" xyz="0 0.0 -0.04"/>
      <geometry>
        <box size="0.01 0.005 0.09"/>
      </geometry>
      <material name="white">
        <color rgba="0.917 0.814 0.261 1"/>
      </material>
    </visual>
  </link>

  <link name="fr4_link">
    <collision>
      <origin rpy="0 0 0" xyz="0 0.0 0.01"/>
      <geometry>
        <sphere radius="0.01"/>
      </geometry>
    </collision>
    <inertial>
      <mass value="0.01"/>
      <inertia ixx="0.001" ixy="0.0" ixz="0.0" iyy="0.001" iyz="0.0" izz="0.001"/>
    </inertial>
    <contact>
        <friction_anchor/>
        <stiffness value="10000.0"/>
        <inertia_scaling value="0.1"/>
        <damping value="10.0"/>
        <lateral_friction value="1"/>
    </contact>
    <visual>
      <origin rpy="0 0 0" xyz="0 0.0 0.01"/>
      <geometry>
        <sphere radius="0.01"/>
      </geometry>
      <material name="white">
        <color rgba="1 1 1 1"/>
      </material>
    </visual>
  </link>

  <link name="bl1_link">
    <collision>
      <origin rpy="0 0 0" xyz="0.0 -0.01 0.01"/>
      <geometry>
        <box size="0.02 0.041 0.041"/>
      </geometry>
    </collision>
    <inertial>
      <mass value="0.07"/>
      <inertia ixx="0.001" ixy="0.0" ixz="0.0" iyy="0.001" iyz="0.0" izz="0.001"/>
    </inertial>
    <visual>
      <origin rpy="0 0 0" xyz="0.0 -0.01 0.01"/>
      <geometry>
        <box size="0.02 0.041 0.041"/>
      </geometry>
      <material name="white">
        <color rgba="0.0 0.56 0.854 1"/>
      </material>
    </visual>
  </link>
   
  <link name="bl2_link">
    <collision>
      <origin rpy="0 0 0" xyz="0 0 -0.03"/>
      <geometry>
        <box size="0.02 0.005 0.1"/>
      </geometry>
    </collision>
    <inertial>
      <mass value="0.07"/>
      <inertia ixx="5.847916666666669e-05" ixy="0.0" ixz="0.0" iyy="6.066666666666668e-05" iyz="0.0" izz="2.479166666666667e-06"/>
    </inertial>
    <visual>
      <origin rpy="0 0 0" xyz="0 0 -0.03"/>
      <geometry>
        <box size="0.02 0.005 0.1"/>
      </geometry>
      <material name="white">
        <color rgba="0.316 0.669 0.261 1"/>
      </material>
    </visual>
  </link>

  <link name="bl3_link">
    <collision>
      <origin rpy="0 0 0" xyz="0 0.0 -0.04"/>
      <geometry>
        <box size="0.01 0.005 0.09"/>
      </geometry>
    </collision>
    <inertial>
      <mass value="0.05"/>
      <inertia ixx="3.3854166666666665e-05" ixy="0.0" ixz="0.0" iyy="3.416666666666666e-05" iyz="0.0" izz="5.208333333333334e-07"/>
    </inertial>
    <visual>
      <origin rpy="0 0 0" xyz="0 0.0 -0.04"/>
      <geometry>
        <box size="0.01 0.005 0.09"/>
      </geometry>
      <material name="white">
        <color rgba="0.917 0.814 0.261 1"/>
      </material>
    </visual>
  </link>

  <link name="bl4_link">
    <collision>
      <origin rpy="0 0 0" xyz="0 0.0 0.01"/>
      <geometry>
        <sphere radius="0.01"/>
      </geometry>
    </collision>
    <inertial>
      <mass value="0.01"/>
      <inertia ixx="0.001" ixy="0.0" ixz="0.0" iyy="0.001" iyz="0.0" izz="0.001"/>
    </inertial>
    <contact>
        <friction_anchor/>
        <stiffness value="10000.0"/>
        <inertia_scaling value="0.1"/>
        <damping value="10.0"/>
        <lateral_friction value="1"/>
    </contact>
    <visual>
      <origin rpy="0 0 0" xyz="0 0.0 0.01"/>
      <geometry>
        <sphere radius="0.01"/>
      </geometry>
      <material name="white">
        <color rgba="1 1 1 1"/>
      </material>
    </visual>
  </link>

  <link name="br1_link">
    <collision>
      <origin rpy="0 0 0" xyz="0.0 0.01 0.01"/>
      <geometry>
        <box size="0.02 0.041 0.041"/>
      </geometry>
    </collision>
    <inertial>
      <mass value="0.07"/>
      <inertia ixx="0.001" ixy="0.0" ixz="0.0" iyy="0.001" iyz="0.0" izz="0.001"/>
    </inertial>
    <visual>
      <origin rpy="0 0 0" xyz="0.0 0.01 0.01"/>
      <geometry>
        <box size="0.02 0.041 0.041"/>
      </geometry>
      <material name="white">
        <color rgba="0.0 0.56 0.854 1"/>
      </material>
    </visual>
  </link>
   
  <link name="br2_link">
    <collision>
      <origin rpy="0 0 0" xyz="0 0 -0.03"/>
      <geometry>
        <box size="0.02 0.005 0.1"/>
      </geometry>
    </collision>
    <inertial>
      <mass value="0.05"/>
      <inertia ixx="4.1770833333333344e-05" ixy="0.0" ixz="0.0" iyy="4.208333333333334e-05" iyz="0.0" izz="5.208333333333334e-07"/>
    </inertial>
    <visual>
      <origin rpy="0 0 0" xyz="0 0 -0.03"/>
      <geometry>
        <box size="0.02 0.005 0.1"/>
      </geometry>
      <material name="white">
        <color rgba="0.316 0.669 0.261 1"/>
      </material>
    </visual>
  </link>

  <link name="br3_link">
    <collision>
      <origin rpy="0 0 0" xyz="0 0.0 -0.04"/>
      <geometry>
        <box size="0.01 0.005 0.09"/>
      </geometry>
    </collision>
    <inertial>
      <mass value="0.05"/>
      <inertia ixx="3.3854166666666665e-05" ixy="0.0" ixz="0.0" iyy="3.416666666666666e-05" iyz="0.0" izz="5.208333333333334e-07"/>
    </inertial>
    <visual>
      <origin rpy="0 0 0" xyz="0 0.0 -0.04"/>
      <geometry>
        <box size="0.01 0.005 0.09"/>
      </geometry>
      <material name="white">
        <color rgba="0.917 0.814 0.261 1"/>
      </material>
    </visual>
  </link>
  
  <link name="br4_link">
    <collision>
      <origin rpy="0 0 0" xyz="0 0.0 0.01"/>
      <geometry>
        <sphere radius="0.01"/>
      </geometry>
    </collision>
    <inertial>
      <mass value="0.01"/>
      <inertia ixx="0.001" ixy="0.0" ixz="0.0" iyy="0.001" iyz="0.0" izz="0.001"/>
    </inertial>
    <contact>
        <friction_anchor/>
        <stiffness value="10000.0"/>
        <inertia_scaling value="0.1"/>
        <damping value="10.0"/>
        <lateral_friction value="1"/>
    </contact>
    <visual>
      <origin rpy="0 0 0" xyz="0 0.0 0.01"/>
      <geometry>
        <sphere radius="0.01"/>
      </geometry>
      <material name="white">
        <color rgba="1 1 1 1"/>
      </material>
    </visual>
  </link>

  <link name="mz_link">
      <collision>
          <origin rpy="0 0 0" xyz="0 0.0 0.0"/>
          <geometry>
              <box size="0.05 0.05 0.01"/>
          </geometry>
      </collision>
      <inertial>
          <mass value="0.0001"/>
          <inertia ixx="0.001" ixy="0.0" ixz="0.0" iyy="0.001" iyz="0.0" izz="0.001"/>
      </inertial>
  </link>
  <link name="my_link">
      <collision>
          <origin rpy="0 0 0" xyz="0 0.0 0.0"/>
          <geometry>
              <box size="0.02 0.02 0.05"/>
          </geometry>
      </collision>
      <inertial>
          <mass value="0.0001"/>
          <inertia ixx="0.001" ixy="0.0" ixz="0.0" iyy="0.001" iyz="0.0" izz="0.001"/>
      </inertial>
  </link>

  <!-- front left -->
 <joint name="fl1" type="revolute">
    <parent link="chassis"/>
    <child link="fl1_link"/>

    <origin xyz="0.115 0.052 0" rpy="0 0 0" />
    <axis xyz="1 0 0" />
    <limit effort="100" velocity="100" lower="-0.398132" upper="0.698132" />
  </joint>

  <joint name="fl2" type="revolute">
    <parent link="fl1_link"/>
    <child link="fl2_link"/>

    <origin xyz="0 0.045 -0.025" rpy="0 0 0" />
    <axis xyz="0 1 0" />
    <limit effort="100" velocity="100" lower="-1.22173" upper="1.22173" />
  </joint>

  <joint name="fl3" type="revolute">
    <parent link="fl2_link"/>
    <child link="fl3_link"/>

    <origin xyz="0 0.0 -0.1" rpy="0 0 0" />
    <axis xyz="0 1 0" />
    <limit effort="100" velocity="100" lower="-3.14159265359" upper="0.0" />
  </joint>

  <joint name="fl4" type="fixed">
    <parent link="fl3_link"/>
    <child link="fl4_link"/>
    
    <origin xyz="0 0 -0.1" rpy="0 0 0" />
    <axis xyz="0 1 0" />
    <limit effort="100" velocity="100" lower="-3.14159265359" upper="3.14159265359" />
  </joint>

  <!-- front right -->
  <joint name="fr1" type="revolute">
    <parent link="chassis"/>
    <child link="fr1_link"/>

    <origin xyz="0.115 -0.052 0" rpy="0 0 0" />
    <axis xyz="1 0 0" />
    <limit effort="100" velocity="100" lower="-0.698132" upper="0.398132" />
  </joint>

  <joint name="fr2" type="revolute">
    <parent link="fr1_link"/>
    <child link="fr2_link"/>

    <origin xyz="0 -0.045 -0.025" rpy="0 0 0" />
    <axis xyz="0 1 0" />
    <limit effort="100" velocity="100" lower="-1.22173" upper="1.22173" />
  </joint>

  <joint name="fr3" type="revolute">
    <parent link="fr2_link"/>
    <child link="fr3_link"/>

    <origin xyz="0 0.0 -0.1" rpy="0 0 0" />
    <axis xyz="0 1 0" />
    <limit effort="100" velocity="100" lower="-3.14159265359" upper="0.0" />
  </joint>

  <joint name="fr4" type="fixed">
    <parent link="fr3_link"/>
    <child link="fr4_link"/>
    
    <origin xyz="0 0 -0.1" rpy="0 0 0" />
    <axis xyz="0 1 0" />
    <limit effort="100" velocity="100" lower="-3.14159265359" upper="3.14159265359" />
  </joint>

<!-- back left -->
 <joint name="bl1" type="revolute">
    <parent link="chassis"/>
    <child link="bl1_link"/>

    <origin xyz="-0.115 0.052 0" rpy="0 0 0" />
    <axis xyz="1 0 0" />
    <limit effort="100" velocity="100" lower="-0.398132" upper="0.698132" />
  </joint>

  <joint name="bl2" type="revolute">
    <parent link="bl1_link"/>
    <child link="bl2_link"/>

    <origin xyz="0 0.045 -0.025" rpy="0 0 0" />
    <axis xyz="0 1 0" />
    <limit effort="100" velocity="100" lower="-1.22173" upper="1.22173" />
  </joint>

  <joint name="bl3" type="revolute">
    <parent link="bl2_link"/>
    <child link="bl3_link"/>

    <origin xyz="0 0.0 -0.1" rpy="0 0 0" />
    <axis xyz="0 1 0" />
    <limit effort="100" velocity="100" lower="-3.14159265359" upper="0.0" />
  </joint>

  <joint name="bl4" type="fixed">
    <parent link="bl3_link"/>
    <child link="bl4_link"/>
    
    <origin xyz="0 0 -0.1" rpy="0 0 0" />
    <axis xyz="0 1 0" />
    <limit effort="100" velocity="100" lower="-3.14159265359" upper="3.14159265359" />
  </joint>

<!-- back right -->
  <joint name="br1" type="revolute">
    <parent link="chassis"/>
    <child link="br1_link"/>

    <origin xyz="-0.115 -0.052 0" rpy="0 0 0" />
    <axis xyz="1 0 0" />
    <limit effort="100" velocity="100" lower="-0.698132" upper="0.398132" />
  </joint>

  <joint name="br2" type="revolute">
    <parent link="br1_link"/>
    <child link="br2_link"/>

    <origin xyz="0 -0.045 -0.025" rpy="0 0 0" />
    <axis xyz="0 1 0" />
    <limit effort="100" velocity="100" lower="-1.22173" upper="1.22173" />
  </joint>

  <joint name="br3" type="revolute">
    <parent link="br2_link"/>
    <child link="br3_link"/>

    <origin xyz="0 0.0 -0.1" rpy="0 0 0" />
    <axis xyz="0 1 0" />
    <limit effort="100" velocity="100" lower="-3.14159265359" upper="0.0" />
  </joint>
  
  <joint name="br4" type="fixed">
    <parent link="br3_link"/>
    <child link="br4_link"/>
    
    <origin xyz="0 0 -0.1" rpy="0 0 0" />
    <axis xyz="0 1 0" />
    <limit effort="100" velocity="100" lower="-3.14159265359" upper="3.14159265359" />
  </joint>

  <joint name="mz" type="revolute">
      <parent link="chassis"/>
      <child link="mz_link"/>
      
      <origin xyz="0.15 0 0" rpy="0 0 0" />
      <axis xyz="0 0 1" />
      <limit effort="100" velocity="100" lower="-1.57079632679" upper="1.57079632679" />
  </joint>

  <joint name="my" type="revolute">
      <parent link="mz_link"/>
      <child link="my_link"/>
      
      <origin xyz="0.03 0 0.03" rpy="0 0 0" />
      <axis xyz="0 1 0" />
      <limit effort="100" velocity="100" lower="-1.57079632679" upper="1.57079632679" />
  </joint>

</robot>
